from ut_utils import ForgeTestCase
from forge import UnexpectedCall
from forge import UnexpectedSetattr

class ContextManager(object):
    def __enter__(self):
        raise NotImplementedError()
    def __exit__(self, t, v, tb):
        raise NotImplementedError()

class ContextManagerTest(ForgeTestCase):
    def setUp(self):
        super(ContextManagerTest, self).setUp()
        self.obj = self.forge.create_mock(ContextManager)
        self.checkpoint = self.forge.create_function_stub(lambda: None)
    def tearDown(self):
        self.assertEquals(len(self.forge.queue), 0)
        self.forge.verify()
        super(ContextManagerTest, self).tearDown()
    def test__expecting_context(self):
        with self.obj:
            self.checkpoint()
        self.forge.replay()
        with self.obj:
            self.checkpoint()
    def test__expecting_context_with_exception_inside(self):
        with self.obj:
            self.checkpoint()
        my_exception = Exception()
        self.forge.replay()
        with self.assertRaises(UnexpectedCall) as caught:
            with self.obj:
                raise my_exception
        caught = caught.exception
        self.assertIs(caught.expected.target, self.checkpoint)
        self.assertIs(caught.got.target.__forge__.original, ContextManager.__exit__)
        self.assertIs(caught.got.args['t'], Exception)
        self.assertIs(caught.got.args['v'], my_exception)
        self.assertIsNotNone(caught.got.args['tb'])
        self.assertEquals(len(self.forge.queue), 2)
        self.forge.reset()
    def test__expecting_context_with_unexpected_call_inside(self):
        stub = self.forge.create_function_stub(lambda arg: None)
        with self.obj:
            stub(1)
        self.forge.replay()
        with self.assertRaises(UnexpectedCall) as caught:
            with self.obj:
                stub(2)
        caught = caught.exception
        self.assertIs(caught.expected.target, stub)
        self.assertIs(caught.got.target, stub)
        self.assertIs(caught.expected.args['arg'], 1)
        self.assertIs(caught.got.args['arg'], 2)
        self.assertEquals(len(self.forge.queue), 2)
        self.forge.reset()
    def test__expecting_context_with_unexpected_setattr_inside(self):
        with self.obj:
            pass
        self.forge.replay()
        with self.assertRaises(UnexpectedSetattr) as caught:
            with self.obj:
                self.obj.a = 2
        caught = caught.exception
        self.assertIs(caught.expected.target, self.obj.__forge__.get_attribute('__exit__'))
        self.assertEquals(len(caught.expected.args), 3)
        self.assertTrue(all(x is None for x in caught.expected.args.values()))
        self.assertIs(caught.got.target, self.obj)
        self.assertEquals(caught.got.name, 'a')
        self.assertEquals(caught.got.value, 2)
        self.assertEquals(len(self.forge.queue), 1)
        self.forge.reset()
    def test__enter_returning_value(self):
        self.obj.__enter__().and_return(2)
        self.checkpoint()
        self.obj.__exit__(None, None, None)
        self.forge.replay()
        with self.obj as value:
            self.checkpoint()
        self.assertEquals(value, 2)

